<dec f='codebrowser/Include/pyerrors.h' l='124' type='void PyException_SetCause(PyObject * , PyObject * )'/>
<use f='codebrowser/Objects/exceptions.c' l='286' u='c' c='BaseException_set_cause'/>
<def f='codebrowser/Objects/exceptions.c' l='324' ll='329' type='void PyException_SetCause(PyObject * self, PyObject * cause)'/>
<use f='codebrowser/Objects/exceptions.c' l='2842' u='c' c='_PyErr_TrySetFromCause'/>
<doc f='codebrowser/Objects/exceptions.c' l='323'>/* Steals a reference to cause */</doc>
<use f='codebrowser/Python/ceval.c' l='4360' u='c' c='do_raise'/>
<use f='codebrowser/Python/errors.c' l='412' u='c' c='_PyErr_FormatVFromCause'/>
